Workbook

Sheet Notes
A2: Important Notes
A4: This spreadsheet will calculate UG and PG loadings based on a fractional load provided.
A5: The calculation is done using the three parameters in the Parameters sheet, the fractional loading and the programmes they are listed against
A6: Each academic should only have a single MSc programme listed, and should have UG listed iff they take UG projects
A7: If an academic takes UG projects (i.e. if UG is listed under programmes), the calculation is round(loading * nominal UG load). Their MSc load is calculated similarly.
A8: If an academic only takes PG projects (i.e. UG is not listed under programmes), the calculation is round(loading * round(nominal UG load / 1.5)) + round(loading * nominal PG load)
A9: After UG allocation, academics that undershoot their loading can have this loading reassigned to PG projects (with the 1.5 weighting applied).
A11: Individual project slots can be added (or theoretically subtracted) from the Extras column.
A12: The programme summary tab will give an overview of the number of slots available for each programme.

Sheet Advisor Loads
A1: First Name | B1: Surname | C1: Username | D1: Programmes | E1: Fractional Loading | F1: UG Slots | G1: UG Extras | H1: UG Undershoot | I1: PG Slots | J1: PG Extras | K1: Total Projects (UG + PG) | L1: Notes
A2: Adrian | B2: Bors | C2: agb11 | D2: UG,AI | E2: 1.5 | F2: =IF(COUNTIF(D2,"*UG*"),ROUND(E2*'Parameters + Programme Summary'!$C$5,0),0) -> 9 | G2: 0 | H2: 1 | I2: =IF(COUNTIF(D2,"*UG*"),ROUND(E2*'Parameters + Programme Summary'!$C$6,0) + ROUND(H2/'Parameters + Programme Summary'!$C$7,0),ROUND(E2*ROUND('Parameters + Programme Summary'!$C$5 / 'Parameters + Programme Summary'!$C$7,0),0)+ROUND(E2*'Parameters + Programme Summary'!$C$6,0)) -> 3 | J2: 0 | K2: =F2+G2-H2+I2+J2 -> 11
A3: Alena | B3: Denisova | C3: ad595 | D3: HCI | E3: 1 | F3: =IF(COUNTIF(D3,"*UG*"),ROUND(E3*'Parameters + Programme Summary'!$C$5,0),0) -> 0 | G3: 0 | H3: 0 | I3: =IF(COUNTIF(D3,"*UG*"),ROUND(E3*'Parameters + Programme Summary'!$C$6,0) + ROUND(H3/'Parameters + Programme Summary'!$C$7,0),ROUND(E3*ROUND('Parameters + Programme Summary'!$C$5 / 'Parameters + Programme Summary'!$C$7,0),0)+ROUND(E3*'Parameters + Programme Summary'!$C$6,0)) -> 5 | J3: 0 | K3: =F3+G3-H3+I3+J3 -> 5
A4: Alvaro | B4: Miyazawa | C4: ahm504 | D4: UG,ACS | E4: 0.5 | F4: =IF(COUNTIF(D4,"*UG*"),ROUND(E4*'Parameters + Programme Summary'!$C$5,0),0) -> 3 | G4: 0 | H4: 0 | I4: =IF(COUNTIF(D4,"*UG*"),ROUND(E4*'Parameters + Programme Summary'!$C$6,0) + ROUND(H4/'Parameters + Programme Summary'!$C$7,0),ROUND(E4*ROUND('Parameters + Programme Summary'!$C$5 / 'Parameters + Programme Summary'!$C$7,0),0)+ROUND(E4*'Parameters + Programme Summary'!$C$6,0)) -> 1 | J4: 0 | K4: =F4+G4-H4+I4+J4 -> 4
A5: Ana | B5: Cavalcanti | D5: NA | E5: 0 | F5: =IF(COUNTIF(D5,"*UG*"),ROUND(E5*'Parameters + Programme Summary'!$C$5,0),0) -> 0 | G5: 0 | H5: 0 | I5: =IF(COUNTIF(D5,"*UG*"),ROUND(E5*'Parameters + Programme Summary'!$C$6,0) + ROUND(H5/'Parameters + Programme Summary'!$C$7,0),ROUND(E5*ROUND('Parameters + Programme Summary'!$C$5 / 'Parameters + Programme Summary'!$C$7,0),0)+ROUND(E5*'Parameters + Programme Summary'!$C$6,0)) -> 0 | J5: 0 | K5: =F5+G5-H5+I5+J5 -> 0
A6: Andy | B6: Pomfret | C6: ajp109 | D6: UG,ACS | E6: 0.75 | F6: =IF(COUNTIF(D6,"*UG*"),ROUND(E6*'Parameters + Programme Summary'!$C$5,0),0) -> 5 | G6: 0 | H6: 2 | I6: =IF(COUNTIF(D6,"*UG*"),ROUND(E6*'Parameters + Programme Summary'!$C$6,0) + ROUND(H6/'Parameters + Programme Summary'!$C$7,0),ROUND(E6*ROUND('Parameters + Programme Summary'!$C$5 / 'Parameters + Programme Summary'!$C$7,0),0)+ROUND(E6*'Parameters + Programme Summary'!$C$6,0)) -> 2 | J6: 0 | K6: =F6+G6-H6+I6+J6 -> 5
A7: Angus | B7: Marshall | C7: amm616 | D7: UG,CYB | E7: 0 | F7: =IF(COUNTIF(D7,"*UG*"),ROUND(E7*'Parameters + Programme Summary'!$C$5,0),0) -> 0 | G7: 0 | H7: 2 | I7: =IF(COUNTIF(D7,"*UG*"),ROUND(E7*'Parameters + Programme Summary'!$C$6,0) + ROUND(H7/'Parameters + Programme Summary'!$C$7,0),ROUND(E7*ROUND('Parameters + Programme Summary'!$C$5 / 'Parameters + Programme Summary'!$C$7,0),0)+ROUND(E7*'Parameters + Programme Summary'!$C$6,0)) -> 1 | J7: 0 | K7: =F7+G7-H7+I7+J7 -> -1
A8: Antonio | B8: Garcia-Dominguez | C8: agd516 | D8: UG,AI | E8: 0.5 | F8: =IF(COUNTIF(D8,"*UG*"),ROUND(E8*'Parameters + Programme Summary'!$C$5,0),0) -> 3 | G8: 0 | H8: 0 | I8: =IF(COUNTIF(D8,"*UG*"),ROUND(E8*'Parameters + Programme Summary'!$C$6,0) + ROUND(H8/'Parameters + Programme Summary'!$C$7,0),ROUND(E8*ROUND('Parameters + Programme Summary'!$C$5 / 'Parameters + Programme Summary'!$C$7,0),0)+ROUND(E8*'Parameters + Programme Summary'!$C$6,0)) -> 1 | J8: 0 | K8: =F8+G8-H8+I8+J8 -> 4
A9: Burak | B9: Merdenyan | C9: bm815 | D9: UG,CYB | E9: 0 | F9: =IF(COUNTIF(D9,"*UG*"),ROUND(E9*'Parameters + Programme Summary'!$C$5,0),0) -> 0 | G9: 0 | H9: 0 | I9: =IF(COUNTIF(D9,"*UG*"),ROUND(E9*'Parameters + Programme Summary'!$C$6,0) + ROUND(H9/'Parameters + Programme Summary'!$C$7,0),ROUND(E9*ROUND('Parameters + Programme Summary'!$C$5 / 'Parameters + Programme Summary'!$C$7,0),0)+ROUND(E9*'Parameters + Programme Summary'!$C$6,0)) -> 0 | J9: 0 | K9: =F9+G9-H9+I9+J9 -> 0
A10: Carlo | B10: Ottaviani | C10: co579 | D10: UG,CYB | E10: 1 | F10: =IF(COUNTIF(D10,"*UG*"),ROUND(E10*'Parameters + Programme Summary'!$C$5,0),0) -> 6 | G10: 0 | H10: 4 | I10: =IF(COUNTIF(D10,"*UG*"),ROUND(E10*'Parameters + Programme Summary'!$C$6,0) + ROUND(H10/'Parameters + Programme Summary'!$C$7,0),ROUND(E10*ROUND('Parameters + Programme Summary'!$C$5 / 'Parameters + Programme Summary'!$C$7,0),0)+ROUND(E10*'Parameters + Programme Summary'!$C$6,0)) -> 4 | J10: 0 | K10: =F10+G10-H10+I10+J10 -> 6 | L10: Not enough UG specs -> sent to CYB. Is taking one MSc student from Maths and so should have one less CS PG project.
A11: Chris | B11: Crispin-Bailey | C11: cb25 | D11: UG,ACS | E11: 1 | F11: =IF(COUNTIF(D11,"*UG*"),ROUND(E11*'Parameters + Programme Summary'!$C$5,0),0) -> 6 | G11: 0 | H11: 1 | I11: =IF(COUNTIF(D11,"*UG*"),ROUND(E11*'Parameters + Programme Summary'!$C$6,0) + ROUND(H11/'Parameters + Programme Summary'!$C$7,0),ROUND(E11*ROUND('Parameters + Programme Summary'!$C$5 / 'Parameters + Programme Summary'!$C$7,0),0)+ROUND(E11*'Parameters + Programme Summary'!$C$6,0)) -> 2 | J11: 0 | K11: =F11+G11-H11+I11+J11 -> 7
A12: Claire | B12: Ingram | C12: ci578 | D12: UG,DATA | E12: 1.5 | F12: =IF(COUNTIF(D12,"*UG*"),ROUND(E12*'Parameters + Programme Summary'!$C$5,0),0) -> 9 | G12: 0 | H12: 3 | I12: =IF(COUNTIF(D12,"*UG*"),ROUND(E12*'Parameters + Programme Summary'!$C$6,0) + ROUND(H12/'Parameters + Programme Summary'!$C$7,0),ROUND(E12*ROUND('Parameters + Programme Summary'!$C$5 / 'Parameters + Programme Summary'!$C$7,0),0)+ROUND(E12*'Parameters + Programme Summary'!$C$6,0)) -> 4 | J12: 0 | K12: =F12+G12-H12+I12+J12 -> 10
A13: Claudio | B13: Guarnera | C13: gcg515 | D13: UG,AI | E13: 0.25 | F13: =IF(COUNTIF(D13,"*UG*"),ROUND(E13*'Parameters + Programme Summary'!$C$5,0),0) -> 2 | G13: 0 | H13: 0 | I13: =IF(COUNTIF(D13,"*UG*"),ROUND(E13*'Parameters + Programme Summary'!$C$6,0) + ROUND(H13/'Parameters + Programme Summary'!$C$7,0),ROUND(E13*ROUND('Parameters + Programme Summary'!$C$5 / 'Parameters + Programme Summary'!$C$7,0),0)+ROUND(E13*'Parameters + Programme Summary'!$C$6,0)) -> 0 | J13: 0 | K13: =F13+G13-H13+I13+J13 -> 2 | L13: No second marking in 2025-26
A14: Colin | B14: Paterson | C14: cap508 | D14: UG,AI | E14: 0.75 | F14: =IF(COUNTIF(D14,"*UG*"),ROUND(E14*'Parameters + Programme Summary'!$C$5,0),0) -> 5 | G14: 0 | H14: 1 | I14: =IF(COUNTIF(D14,"*UG*"),ROUND(E14*'Parameters + Programme Summary'!$C$6,0) + ROUND(H14/'Parameters + Programme Summary'!$C$7,0),ROUND(E14*ROUND('Parameters + Programme Summary'!$C$5 / 'Parameters + Programme Summary'!$C$7,0),0)+ROUND(E14*'Parameters + Programme Summary'!$C$6,0)) -> 2 | J14: 0 | K14: =F14+G14-H14+I14+J14 -> 6
A15: David | B15: Pumfrey | D15: SCSE | E15: 0 | F15: =IF(COUNTIF(D15,"*UG*"),ROUND(E15*'Parameters + Programme Summary'!$C$5,0),0) -> 0 | G15: 0 | H15: 0 | I15: =IF(COUNTIF(D15,"*UG*"),ROUND(E15*'Parameters + Programme Summary'!$C$6,0) + ROUND(H15/'Parameters + Programme Summary'!$C$7,0),ROUND(E15*ROUND('Parameters + Programme Summary'!$C$5 / 'Parameters + Programme Summary'!$C$7,0),0)+ROUND(E15*'Parameters + Programme Summary'!$C$6,0)) -> 0 | J15: 0 | K15: =F15+G15-H15+I15+J15 -> 0
A16: Dawn | B16: Wood | C16: dhw506 | D16: UG,ACS | E16: 1.5 | F16: =IF(COUNTIF(D16,"*UG*"),ROUND(E16*'Parameters + Programme Summary'!$C$5,0),0) -> 9 | G16: 0 | H16: 1 | I16: =IF(COUNTIF(D16,"*UG*"),ROUND(E16*'Parameters + Programme Summary'!$C$6,0) + ROUND(H16/'Parameters + Programme Summary'!$C$7,0),ROUND(E16*ROUND('Parameters + Programme Summary'!$C$5 / 'Parameters + Programme Summary'!$C$7,0),0)+ROUND(E16*'Parameters + Programme Summary'!$C$6,0)) -> 3 | J16: 0 | K16: =F16+G16-H16+I16+J16 -> 11
A17: Detlef | B17: Plump | C17: djp10 | D17: UG,ACS | E17: 1 | F17: =IF(COUNTIF(D17,"*UG*"),ROUND(E17*'Parameters + Programme Summary'!$C$5,0),0) -> 6 | G17: 0 | H17: 2 | I17: =IF(COUNTIF(D17,"*UG*"),ROUND(E17*'Parameters + Programme Summary'!$C$6,0) + ROUND(H17/'Parameters + Programme Summary'!$C$7,0),ROUND(E17*ROUND('Parameters + Programme Summary'!$C$5 / 'Parameters + Programme Summary'!$C$7,0),0)+ROUND(E17*'Parameters + Programme Summary'!$C$6,0)) -> 2 | J17: 0 | K17: =F17+G17-H17+I17+J17 -> 6
A18: Dimitar | B18: Kazakov | C18: dlk2 | D18: UG,DATA | E18: 1 | F18: =IF(COUNTIF(D18,"*UG*"),ROUND(E18*'Parameters + Programme Summary'!$C$5,0),0) -> 6 | G18: 0 | H18: 1 | I18: =IF(COUNTIF(D18,"*UG*"),ROUND(E18*'Parameters + Programme Summary'!$C$6,0) + ROUND(H18/'Parameters + Programme Summary'!$C$7,0),ROUND(E18*ROUND('Parameters + Programme Summary'!$C$5 / 'Parameters + Programme Summary'!$C$7,0),0)+ROUND(E18*'Parameters + Programme Summary'!$C$6,0)) -> 2 | J18: 0 | K18: =F18+G18-H18+I18+J18 -> 7
A19: Dimitris | B19: Kolovos | C19: dk135 | D19: UG,ACS | E19: 0 | F19: =IF(COUNTIF(D19,"*UG*"),ROUND(E19*'Parameters + Programme Summary'!$C$5,0),0) -> 0 | G19: 0 | H19: 0 | I19: =IF(COUNTIF(D19,"*UG*"),ROUND(E19*'Parameters + Programme Summary'!$C$6,0) + ROUND(H19/'Parameters + Programme Summary'!$C$7,0),ROUND(E19*ROUND('Parameters + Programme Summary'!$C$5 / 'Parameters + Programme Summary'!$C$7,0),0)+ROUND(E19*'Parameters + Programme Summary'!$C$6,0)) -> 0 | J19: 0 | K19: =F19+G19-H19+I19+J19 -> 0
A20: Frank | B20: Soboczenski | C20: fs596 | D20: DATA | E20: 0 | F20: =IF(COUNTIF(D20,"*UG*"),ROUND(E20*'Parameters + Programme Summary'!$C$5,0),0) -> 0 | G20: 0 | H20: 0 | I20: =IF(COUNTIF(D20,"*UG*"),ROUND(E20*'Parameters + Programme Summary'!$C$6,0) + ROUND(H20/'Parameters + Programme Summary'!$C$7,0),ROUND(E20*ROUND('Parameters + Programme Summary'!$C$5 / 'Parameters + Programme Summary'!$C$7,0),0)+ROUND(E20*'Parameters + Programme Summary'!$C$6,0)) -> 0 | J20: 0 | K20: =F20+G20-H20+I20+J20 -> 0 | L20: No MSc projects for AY 2025/26 | M20: Changed fractional loading to 0 for this year
A21: Iain | B21: Bate | C21: ijb500 | D21: UG,ACS | E21: 0 | F21: =IF(COUNTIF(D21,"*UG*"),ROUND(E21*'Parameters + Programme Summary'!$C$5,0),0) -> 0 | G21: 0 | H21: 0 | I21: =IF(COUNTIF(D21,"*UG*"),ROUND(E21*'Parameters + Programme Summary'!$C$6,0) + ROUND(H21/'Parameters + Programme Summary'!$C$7,0),ROUND(E21*ROUND('Parameters + Programme Summary'!$C$5 / 'Parameters + Programme Summary'!$C$7,0),0)+ROUND(E21*'Parameters + Programme Summary'!$C$6,0)) -> 0 | J21: 0 | K21: =F21+G21-H21+I21+J21 -> 0
A22: Ian | B22: Gray | C22: ig112 | D22: UG,ACS | E22: 0 | F22: =IF(COUNTIF(D22,"*UG*"),ROUND(E22*'Parameters + Programme Summary'!$C$5,0),0) -> 0 | G22: 0 | H22: 0 | I22: =IF(COUNTIF(D22,"*UG*"),ROUND(E22*'Parameters + Programme Summary'!$C$6,0) + ROUND(H22/'Parameters + Programme Summary'!$C$7,0),ROUND(E22*ROUND('Parameters + Programme Summary'!$C$5 / 'Parameters + Programme Summary'!$C$7,0),0)+ROUND(E22*'Parameters + Programme Summary'!$C$6,0)) -> 0 | J22: 0 | K22: =F22+G22-H22+I22+J22 -> 0
A23: Ibrahim | B23: Habli | C23: ih126 | D23: UG,SCSE | E23: 0 | F23: =IF(COUNTIF(D23,"*UG*"),ROUND(E23*'Parameters + Programme Summary'!$C$5,0),0) -> 0 | G23: 0 | H23: 0 | I23: =IF(COUNTIF(D23,"*UG*"),ROUND(E23*'Parameters + Programme Summary'!$C$6,0) + ROUND(H23/'Parameters + Programme Summary'!$C$7,0),ROUND(E23*ROUND('Parameters + Programme Summary'!$C$5 / 'Parameters + Programme Summary'!$C$7,0),0)+ROUND(E23*'Parameters + Programme Summary'!$C$6,0)) -> 0 | J23: 0 | K23: =F23+G23-H23+I23+J23 -> 0
A24: Jacob | B24: Rigby | C24: rxw517 | D24: UG,ACS | E24: 0.5 | F24: =IF(COUNTIF(D24,"*UG*"),ROUND(E24*'Parameters + Programme Summary'!$C$5,0),0) -> 3 | G24: 1 | H24: 0 | I24: =IF(COUNTIF(D24,"*UG*"),ROUND(E24*'Parameters + Programme Summary'!$C$6,0) + ROUND(H24/'Parameters + Programme Summary'!$C$7,0),ROUND(E24*ROUND('Parameters + Programme Summary'!$C$5 / 'Parameters + Programme Summary'!$C$7,0),0)+ROUND(E24*'Parameters + Programme Summary'!$C$6,0)) -> 1 | J24: 0 | K24: =F24+G24-H24+I24+J24 -> 5 | L24: No MSc projects in 2025-26 | M24: Left at 0 in TP despite 1 PG slot here
A25: James | B25: Walker | C25: jaw500 | D25: UG,AI | E25: 0.75 | F25: =IF(COUNTIF(D25,"*UG*"),ROUND(E25*'Parameters + Programme Summary'!$C$5,0),0) -> 5 | G25: 0 | H25: -1 | I25: =IF(COUNTIF(D25,"*UG*"),ROUND(E25*'Parameters + Programme Summary'!$C$6,0) + ROUND(H25/'Parameters + Programme Summary'!$C$7,0),ROUND(E25*ROUND('Parameters + Programme Summary'!$C$5 / 'Parameters + Programme Summary'!$C$7,0),0)+ROUND(E25*'Parameters + Programme Summary'!$C$6,0)) -> 0 | J25: 0 | K25: =F25+G25-H25+I25+J25 -> 6
A26: Jen | B26: Beeston | C26: jb558 | D26: UG,HCI | E26: 0.5 | F26: =IF(COUNTIF(D26,"*UG*"),ROUND(E26*'Parameters + Programme Summary'!$C$5,0),0) -> 3 | G26: 0 | H26: 0 | I26: =IF(COUNTIF(D26,"*UG*"),ROUND(E26*'Parameters + Programme Summary'!$C$6,0) + ROUND(H26/'Parameters + Programme Summary'!$C$7,0),ROUND(E26*ROUND('Parameters + Programme Summary'!$C$5 / 'Parameters + Programme Summary'!$C$7,0),0)+ROUND(E26*'Parameters + Programme Summary'!$C$6,0)) -> 1 | J26: 0 | K26: =F26+G26-H26+I26+J26 -> 4 | L26: Producing learning materials for PRBX | M26: Checked with Jen, she is not expecting any MScs so I have set it to 0 in the TP
A27: Jo | B27: Iacovides | C27: ii560 | D27: UG,HCI | E27: 1 | F27: =IF(COUNTIF(D27,"*UG*"),ROUND(E27*'Parameters + Programme Summary'!$C$5,0),0) -> 6 | G27: 0 | H27: 4 | I27: =IF(COUNTIF(D27,"*UG*"),ROUND(E27*'Parameters + Programme Summary'!$C$6,0) + ROUND(H27/'Parameters + Programme Summary'!$C$7,0),ROUND(E27*ROUND('Parameters + Programme Summary'!$C$5 / 'Parameters + Programme Summary'!$C$7,0),0)+ROUND(E27*'Parameters + Programme Summary'!$C$6,0)) -> 4 | J27: 0 | K27: =F27+G27-H27+I27+J27 -> 6
A28: Joe | B28: Cutting | C28: jtc511 | D28: UG,HCI | E28: 1 | F28: =IF(COUNTIF(D28,"*UG*"),ROUND(E28*'Parameters + Programme Summary'!$C$5,0),0) -> 6 | G28: 0 | H28: 1 | I28: =IF(COUNTIF(D28,"*UG*"),ROUND(E28*'Parameters + Programme Summary'!$C$6,0) + ROUND(H28/'Parameters + Programme Summary'!$C$7,0),ROUND(E28*ROUND('Parameters + Programme Summary'!$C$5 / 'Parameters + Programme Summary'!$C$7,0),0)+ROUND(E28*'Parameters + Programme Summary'!$C$6,0)) -> 2 | J28: 0 | K28: =F28+G28-H28+I28+J28 -> 7
A29: John | B29: Oyekan | C29: jo861 | D29: UG,AI | E29: 1 | F29: =IF(COUNTIF(D29,"*UG*"),ROUND(E29*'Parameters + Programme Summary'!$C$5,0),0) -> 6 | G29: 0 | H29: 0 | I29: =IF(COUNTIF(D29,"*UG*"),ROUND(E29*'Parameters + Programme Summary'!$C$6,0) + ROUND(H29/'Parameters + Programme Summary'!$C$7,0),ROUND(E29*ROUND('Parameters + Programme Summary'!$C$5 / 'Parameters + Programme Summary'!$C$7,0),0)+ROUND(E29*'Parameters + Programme Summary'!$C$6,0)) -> 1 | J29: 0 | K29: =F29+G29-H29+I29+J29 -> 7
A30: Katrina | B30: Attwood | C30: kca3 | D30: UG | E30: 0.75 | F30: =IF(COUNTIF(D30,"*UG*"),ROUND(E30*'Parameters + Programme Summary'!$C$5,0),0) -> 5 | G30: 0 | H30: 0 | I30: =IF(COUNTIF(D30,"*UG*"),ROUND(E30*'Parameters + Programme Summary'!$C$6,0) + ROUND(H30/'Parameters + Programme Summary'!$C$7,0),ROUND(E30*ROUND('Parameters + Programme Summary'!$C$5 / 'Parameters + Programme Summary'!$C$7,0),0)+ROUND(E30*'Parameters + Programme Summary'!$C$6,0)) -> 1 | J30: 0 | K30: =F30+G30-H30+I30+J30 -> 6 | L30: No MSc students -- entire load as UG | M30: Left at 0 in TP despite 1 PG slot here
A31: Kofi | B31: Appiah | C31: kea523 | D31: UG,DATA | E31: 1 | F31: =IF(COUNTIF(D31,"*UG*"),ROUND(E31*'Parameters + Programme Summary'!$C$5,0),0) -> 6 | G31: 0 | H31: 0 | I31: =IF(COUNTIF(D31,"*UG*"),ROUND(E31*'Parameters + Programme Summary'!$C$6,0) + ROUND(H31/'Parameters + Programme Summary'!$C$7,0),ROUND(E31*ROUND('Parameters + Programme Summary'!$C$5 / 'Parameters + Programme Summary'!$C$7,0),0)+ROUND(E31*'Parameters + Programme Summary'!$C$6,0)) -> 1 | J31: 0 | K31: =F31+G31-H31+I31+J31 -> 7
A32: Konstantinos | B32: Barmpis | C32: kb634 | D32: UG,ACS | E32: 0.25 | F32: =IF(COUNTIF(D32,"*UG*"),ROUND(E32*'Parameters + Programme Summary'!$C$5,0),0) -> 2 | G32: 0 | H32: 0 | I32: =IF(COUNTIF(D32,"*UG*"),ROUND(E32*'Parameters + Programme Summary'!$C$6,0) + ROUND(H32/'Parameters + Programme Summary'!$C$7,0),ROUND(E32*ROUND('Parameters + Programme Summary'!$C$5 / 'Parameters + Programme Summary'!$C$7,0),0)+ROUND(E32*'Parameters + Programme Summary'!$C$6,0)) -> 0 | J32: 0 | K32: =F32+G32-H32+I32+J32 -> 2
A33: Lilian | B33: Blot | C33: lb1008 | D33: UG,ACS | E33: 0 | F33: =IF(COUNTIF(D33,"*UG*"),ROUND(E33*'Parameters + Programme Summary'!$C$5,0),0) -> 0 | G33: 0 | H33: 0 | I33: =IF(COUNTIF(D33,"*UG*"),ROUND(E33*'Parameters + Programme Summary'!$C$6,0) + ROUND(H33/'Parameters + Programme Summary'!$C$7,0),ROUND(E33*ROUND('Parameters + Programme Summary'!$C$5 / 'Parameters + Programme Summary'!$C$7,0),0)+ROUND(E33*'Parameters + Programme Summary'!$C$6,0)) -> 0 | J33: 0 | K33: =F33+G33-H33+I33+J33 -> 0 | L33: Online programme
A34: Mark | B34: Nicholson | C34: mn103 | D34: SCSE | E34: 0.9 | F34: =IF(COUNTIF(D34,"*UG*"),ROUND(E34*'Parameters + Programme Summary'!$C$5,0),0) -> 0 | G34: 0 | H34: 0 | I34: =IF(COUNTIF(D34,"*UG*"),ROUND(E34*'Parameters + Programme Summary'!$C$6,0) + ROUND(H34/'Parameters + Programme Summary'!$C$7,0),ROUND(E34*ROUND('Parameters + Programme Summary'!$C$5 / 'Parameters + Programme Summary'!$C$7,0),0)+ROUND(E34*'Parameters + Programme Summary'!$C$6,0)) -> 5 | J34: 0 | K34: =F34+G34-H34+I34+J34 -> 5
A35: Mike | B35: Freeman | C35: mjf5 | D35: UG,ACS | E35: 0 | F35: =IF(COUNTIF(D35,"*UG*"),ROUND(E35*'Parameters + Programme Summary'!$C$5,0),0) -> 0 | G35: 0 | H35: 0 | I35: =IF(COUNTIF(D35,"*UG*"),ROUND(E35*'Parameters + Programme Summary'!$C$6,0) + ROUND(H35/'Parameters + Programme Summary'!$C$7,0),ROUND(E35*ROUND('Parameters + Programme Summary'!$C$5 / 'Parameters + Programme Summary'!$C$7,0),0)+ROUND(E35*'Parameters + Programme Summary'!$C$6,0)) -> 0 | J35: 0 | K35: =F35+G35-H35+I35+J35 -> 0
A36: Mike | B36: O'Dea | C36: nlr532 | D36: UG,DATA | E36: 1.2 | F36: =IF(COUNTIF(D36,"*UG*"),ROUND(E36*'Parameters + Programme Summary'!$C$5,0),0) -> 7 | G36: 0 | H36: 2 | I36: =IF(COUNTIF(D36,"*UG*"),ROUND(E36*'Parameters + Programme Summary'!$C$6,0) + ROUND(H36/'Parameters + Programme Summary'!$C$7,0),ROUND(E36*ROUND('Parameters + Programme Summary'!$C$5 / 'Parameters + Programme Summary'!$C$7,0),0)+ROUND(E36*'Parameters + Programme Summary'!$C$6,0)) -> 2 | J36: 0 | M36: UG undershoot initally 3 as per Simon, calculated 2
A37: Nick | B37: Pears | C37: np7 | D37: UG,AI | E37: 0.5 | F37: =IF(COUNTIF(D37,"*UG*"),ROUND(E37*'Parameters + Programme Summary'!$C$5,0),0) -> 3 | G37: 0 | H37: 0 | I37: =IF(COUNTIF(D37,"*UG*"),ROUND(E37*'Parameters + Programme Summary'!$C$6,0) + ROUND(H37/'Parameters + Programme Summary'!$C$7,0),ROUND(E37*ROUND('Parameters + Programme Summary'!$C$5 / 'Parameters + Programme Summary'!$C$7,0),0)+ROUND(E37*'Parameters + Programme Summary'!$C$6,0)) -> 1 | J37: 0 | K37: =F37+G37-H37+I37+J37 -> 4
A38: Oleg | B38: Lisagor | C38: ol101 | D38: SCSE | E38: 1 | F38: =IF(COUNTIF(D38,"*UG*"),ROUND(E38*'Parameters + Programme Summary'!$C$5,0),0) -> 0 | G38: 0 | H38: 0 | I38: =IF(COUNTIF(D38,"*UG*"),ROUND(E38*'Parameters + Programme Summary'!$C$6,0) + ROUND(H38/'Parameters + Programme Summary'!$C$7,0),ROUND(E38*ROUND('Parameters + Programme Summary'!$C$5 / 'Parameters + Programme Summary'!$C$7,0),0)+ROUND(E38*'Parameters + Programme Summary'!$C$6,0)) -> 5 | J38: 0 | K38: =F38+G38-H38+I38+J38 -> 5 | L38: SCSE self-defined and overflow. No UG projects. Will help marking.
A39: Paul | B39: Cairns | C39: pc530 | D39: UG,ACS | E39: 0.75 | F39: =IF(COUNTIF(D39,"*UG*"),ROUND(E39*'Parameters + Programme Summary'!$C$5,0),0) -> 5 | G39: 0 | H39: 1 | I39: =IF(COUNTIF(D39,"*UG*"),ROUND(E39*'Parameters + Programme Summary'!$C$6,0) + ROUND(H39/'Parameters + Programme Summary'!$C$7,0),ROUND(E39*ROUND('Parameters + Programme Summary'!$C$5 / 'Parameters + Programme Summary'!$C$7,0),0)+ROUND(E39*'Parameters + Programme Summary'!$C$6,0)) -> 2 | J39: 0 | K39: =F39+G39-H39+I39+J39 -> 6 | M39: Loading in the TP was 4 despite 5 here, so no remaining. Have gone with the spreadsheet. Also, reserve for DATA?
A40: Pedro | B40: Ribeiro | C40: pfr500 | D40: UG,ACS | E40: 0.5 | F40: =IF(COUNTIF(D40,"*UG*"),ROUND(E40*'Parameters + Programme Summary'!$C$5,0),0) -> 3 | G40: 0 | H40: 1 | I40: =IF(COUNTIF(D40,"*UG*"),ROUND(E40*'Parameters + Programme Summary'!$C$6,0) + ROUND(H40/'Parameters + Programme Summary'!$C$7,0),ROUND(E40*ROUND('Parameters + Programme Summary'!$C$5 / 'Parameters + Programme Summary'!$C$7,0),0)+ROUND(E40*'Parameters + Programme Summary'!$C$6,0)) -> 2 | J40: 0 | K40: =F40+G40-H40+I40+J40 -> 4
...

Sheet Parameters + Programme Summary
B4: Parameters
B5: Nominal UG Load | C5: 6
B6: Nominal PG Load | C6: 1
B7: PG to UG Weighting | C7: 1.5
B9: Summary
B10: Programme | C10: Slots | D10: Total students this year
B11: ACS | C11: =SUMIF('Advisor Loads'!$D$2:$D$100,"*"&'Parameters + Programme Summary'!B11&"*",'Advisor Loads'!$I$2:$I$61)+SUMIF('Advisor Loads'!$D$2:$D$61,"*"&'Parameters + Programme Summary'!B11&"*",'Advisor Loads'!$J$2:$J$61) -> 23 | D11: 11
B12: HCI | C12: =SUMIF('Advisor Loads'!$D$2:$D$100,"*"&'Parameters + Programme Summary'!B12&"*",'Advisor Loads'!$I$2:$I$61)+SUMIF('Advisor Loads'!$D$2:$D$61,"*"&'Parameters + Programme Summary'!B12&"*",'Advisor Loads'!$J$2:$J$61) -> 12 | D12: 7
B13: CYB | C13: =SUMIF('Advisor Loads'!$D$2:$D$100,"*"&'Parameters + Programme Summary'!B13&"*",'Advisor Loads'!$I$2:$I$61)+SUMIF('Advisor Loads'!$D$2:$D$61,"*"&'Parameters + Programme Summary'!B13&"*",'Advisor Loads'!$J$2:$J$61) -> 16 | D13: 20
B14: SCSE | C14: =SUMIF('Advisor Loads'!$D$2:$D$100,"*"&'Parameters + Programme Summary'!B14&"*",'Advisor Loads'!$I$2:$I$61)+SUMIF('Advisor Loads'!$D$2:$D$61,"*"&'Parameters + Programme Summary'!B14&"*",'Advisor Loads'!$J$2:$J$61) -> 20 | D14: 11
B15: AI | C15: =SUMIF('Advisor Loads'!$D$2:$D$100,"*"&'Parameters + Programme Summary'!B15&"*",'Advisor Loads'!$I$2:$I$61)+SUMIF('Advisor Loads'!$D$2:$D$61,"*"&'Parameters + Programme Summary'!B15&"*",'Advisor Loads'!$J$2:$J$61) -> 18 | D15: 14
B16: DATA | C16: =SUMIF('Advisor Loads'!$D$2:$D$100,"*"&'Parameters + Programme Summary'!B16&"*",'Advisor Loads'!$I$2:$I$61)+SUMIF('Advisor Loads'!$D$2:$D$61,"*"&'Parameters + Programme Summary'!B16&"*",'Advisor Loads'!$J$2:$J$61) -> 14 | D16: 13
B18: Totals
B19: UG | C19: =SUMIF('Advisor Loads'!$D$2:$D$100,"*"&'Parameters + Programme Summary'!B19&"*",'Advisor Loads'!$F$2:$F$100)+SUMIF('Advisor Loads'!$D$2:$D$100,"*"&'Parameters + Programme Summary'!B19&"*",'Advisor Loads'!$G$2:$G$100)-SUMIF('Advisor Loads'!$D$2:$D$100,"*"&'Parameters + Programme Summary'!B19&"*",'Advisor Loads'!$H$2:$H$100) -> 177
B20: PG | C20: =SUM(C11:C16) -> 103
